2023-01-09 18:44:31,488 - WARNING - connectionpool.py - urlopen - MainThread: Retrying (Retry(total=2, connect=None, read=None, redirect=None, status=None)) after connection broken by 'NewConnectionError('<urllib3.connection.HTTPConnection object at 0x7f9dae1f5190>: Failed to establish a new connection: [Errno 61] Connection refused')': /wd/hub/session
2023-01-09 18:44:31,490 - WARNING - connectionpool.py - urlopen - MainThread: Retrying (Retry(total=1, connect=None, read=None, redirect=None, status=None)) after connection broken by 'NewConnectionError('<urllib3.connection.HTTPConnection object at 0x7f9dae1f5910>: Failed to establish a new connection: [Errno 61] Connection refused')': /wd/hub/session
2023-01-09 18:44:31,492 - WARNING - connectionpool.py - urlopen - MainThread: Retrying (Retry(total=0, connect=None, read=None, redirect=None, status=None)) after connection broken by 'NewConnectionError('<urllib3.connection.HTTPConnection object at 0x7f9dae207be0>: Failed to establish a new connection: [Errno 61] Connection refused')': /wd/hub/session
2023-01-09 18:44:55,237 - WARNING - connectionpool.py - urlopen - MainThread: Retrying (Retry(total=2, connect=None, read=None, redirect=None, status=None)) after connection broken by 'NewConnectionError('<urllib3.connection.HTTPConnection object at 0x7f90e61f5100>: Failed to establish a new connection: [Errno 61] Connection refused')': /wd/hub/session
2023-01-09 18:44:55,239 - WARNING - connectionpool.py - urlopen - MainThread: Retrying (Retry(total=1, connect=None, read=None, redirect=None, status=None)) after connection broken by 'NewConnectionError('<urllib3.connection.HTTPConnection object at 0x7f90e61f58b0>: Failed to establish a new connection: [Errno 61] Connection refused')': /wd/hub/session
2023-01-09 18:44:55,241 - WARNING - connectionpool.py - urlopen - MainThread: Retrying (Retry(total=0, connect=None, read=None, redirect=None, status=None)) after connection broken by 'NewConnectionError('<urllib3.connection.HTTPConnection object at 0x7f90e6206b50>: Failed to establish a new connection: [Errno 61] Connection refused')': /wd/hub/session
2023-01-09 18:46:38,599 - WARNING - connectionpool.py - urlopen - MainThread: Retrying (Retry(total=2, connect=None, read=None, redirect=None, status=None)) after connection broken by 'NewConnectionError('<urllib3.connection.HTTPConnection object at 0x7f98661f77c0>: Failed to establish a new connection: [Errno 61] Connection refused')': /wd/hub/session
2023-01-09 18:46:38,601 - WARNING - connectionpool.py - urlopen - MainThread: Retrying (Retry(total=1, connect=None, read=None, redirect=None, status=None)) after connection broken by 'NewConnectionError('<urllib3.connection.HTTPConnection object at 0x7f98661f7880>: Failed to establish a new connection: [Errno 61] Connection refused')': /wd/hub/session
2023-01-09 18:46:38,603 - WARNING - connectionpool.py - urlopen - MainThread: Retrying (Retry(total=0, connect=None, read=None, redirect=None, status=None)) after connection broken by 'NewConnectionError('<urllib3.connection.HTTPConnection object at 0x7f9866206af0>: Failed to establish a new connection: [Errno 61] Connection refused')': /wd/hub/session
2023-01-09 18:48:56,306 - WARNING - connectionpool.py - urlopen - MainThread: Retrying (Retry(total=2, connect=None, read=None, redirect=None, status=None)) after connection broken by 'NewConnectionError('<urllib3.connection.HTTPConnection object at 0x7f79800da100>: Failed to establish a new connection: [Errno 61] Connection refused')': /wd/hub/session
2023-01-09 18:48:56,307 - WARNING - connectionpool.py - urlopen - MainThread: Retrying (Retry(total=1, connect=None, read=None, redirect=None, status=None)) after connection broken by 'NewConnectionError('<urllib3.connection.HTTPConnection object at 0x7f79800da880>: Failed to establish a new connection: [Errno 61] Connection refused')': /wd/hub/session
2023-01-09 18:48:56,309 - WARNING - connectionpool.py - urlopen - MainThread: Retrying (Retry(total=0, connect=None, read=None, redirect=None, status=None)) after connection broken by 'NewConnectionError('<urllib3.connection.HTTPConnection object at 0x7f7980206b50>: Failed to establish a new connection: [Errno 61] Connection refused')': /wd/hub/session
2023-01-09 18:50:33,231 - INFO - conftest.py - Appium_driver - MainThread: 已启动app!
2023-01-09 18:50:37,725 - INFO - conftest.py - _click_element - MainThread: 已点击元素:[喜马拉雅]
2023-01-09 19:17:12,599 - INFO - conftest.py - Appium_driver - MainThread: 已启动app!
2023-01-09 19:17:17,208 - INFO - conftest.py - _click_element - MainThread: 已点击元素:[喜马拉雅]
2023-01-09 19:17:21,593 - INFO - conftest.py - _click_element - MainThread: 已点击元素:[喜马拉雅]
2023-01-09 19:17:24,265 - INFO - conftest.py - _click_element - MainThread: 已点击元素:[喜马拉雅]
